1970-01-01T00:33:41+00:00	docker.logs	{"log":"2021-12-01 11:05:39.410673 I | etcdserver/api/etcdhttp: /health OK (status code 200)\n","stream":"stderr"}
1970-01-01T00:33:41+00:00	docker.logs	{"log":"W1201 11:05:39.783319       1 watcher.go:220] watch chan error: etcdserver: mvcc: required revision has been compacted\n","stream":"stderr"}
1970-01-01T00:33:41+00:00	docker.logs	{"log":"W1201 11:05:44.851195       1 watcher.go:220] watch chan error: etcdserver: mvcc: required revision has been compacted\n","stream":"stderr"}
1970-01-01T00:33:41+00:00	docker.logs	{"log":"2021-12-01 11:05:49.410930 I | etcdserver/api/etcdhttp: /health OK (status code 200)\n","stream":"stderr"}
1970-01-01T00:33:41+00:00	docker.logs	{"log":"W1201 11:05:51.436663       1 watcher.go:220] watch chan error: etcdserver: mvcc: required revision has been compacted\n","stream":"stderr"}
1970-01-01T00:33:41+00:00	docker.logs	{"log":"E1201 11:05:54.202108       1 dynamic_cafile_content.go:202] key failed with : open /run/config/pki/ca.crt: no such file or directory\n","stream":"stderr"}
1970-01-01T00:33:41+00:00	docker.logs	{"log":"E1201 11:05:54.202108       1 dynamic_cafile_content.go:202] key failed with : open /run/config/pki/front-proxy-ca.crt: no such file or directory\n","stream":"stderr"}
1970-01-01T00:33:41+00:00	docker.logs	{"log":"I1201 11:05:56.499465       1 client.go:360] parsed scheme: \"passthrough\"\n","stream":"stderr"}
1970-01-01T00:33:41+00:00	docker.logs	{"log":"I1201 11:05:56.499506       1 passthrough.go:48] ccResolverWrapper: sending update to cc: {[{https://127.0.0.1:2379  <nil> 0 <nil>}] <nil> <nil>}\n","stream":"stderr"}
1970-01-01T00:33:41+00:00	docker.logs	{"log":"I1201 11:05:56.499514       1 clientconn.go:948] ClientConn switching balancer to \"pick_first\"\n","stream":"stderr"}
1970-01-01T00:33:41+00:00	docker.logs	{"log":"W1201 11:05:56.500515       1 clientconn.go:1223] grpc: addrConn.createTransport failed to connect to {https://127.0.0.1:2379  <nil> 0 <nil>}. Err :connection error: desc = \"transport: authentication handshake failed: remote error: tls: internal error\". Reconnecting...\n","stream":"stderr"}
1970-01-01T00:33:41+00:00	docker.logs	{"log":"2021-12-01 11:05:56.500211 I | embed: rejected connection from \"127.0.0.1:55390\" (error \"open /run/config/pki/etcd/server.crt: no such file or directory\", ServerName \"\")\n","stream":"stderr"}
1970-01-01T00:33:41+00:00	docker.logs	{"log":"2021-12-01 11:05:57.509208 I | embed: rejected connection from \"127.0.0.1:55400\" (error \"open /run/config/pki/etcd/server.crt: no such file or directory\", ServerName \"\")\n","stream":"stderr"}
1970-01-01T00:33:41+00:00	docker.logs	{"log":"W1201 11:05:57.509716       1 clientconn.go:1223] grpc: addrConn.createTransport failed to connect to {https://127.0.0.1:2379  <nil> 0 <nil>}. Err :connection error: desc = \"transport: authentication handshake failed: remote error: tls: internal error\". Reconnecting...\n","stream":"stderr"}
1970-01-01T00:33:41+00:00	docker.logs	{"log":"2021-12-01 11:05:58.847574 I | embed: rejected connection from \"127.0.0.1:55410\" (error \"open /run/config/pki/etcd/server.crt: no such file or directory\", ServerName \"\")\n","stream":"stderr"}
1970-01-01T00:33:41+00:00	docker.logs	{"log":"W1201 11:05:58.849208       1 clientconn.go:1223] grpc: addrConn.createTransport failed to connect to {https://127.0.0.1:2379  <nil> 0 <nil>}. Err :connection error: desc = \"transport: authentication handshake failed: remote error: tls: internal error\". Reconnecting...\n","stream":"stderr"}
1970-01-01T00:33:41+00:00	docker.logs	{"log":"2021-12-01 11:05:58.858268 I | mvcc: store.index: compact 1437768\n","stream":"stderr"}
1970-01-01T00:33:41+00:00	docker.logs	{"log":"2021-12-01 11:05:58.862944 I | mvcc: finished scheduled compaction at 1437768 (took 2.877779ms)\n","stream":"stderr"}
1970-01-01T00:33:41+00:00	docker.logs	{"log":"2021-12-01 11:05:59.412427 I | etcdserver/api/etcdhttp: /health OK (status code 200)\n","stream":"stderr"}
1970-01-01T00:33:41+00:00	docker.logs	{"log":"time=\"2021-12-01T11:05:59Z\" level=error msg=\"Port 30000 for service reactapp-service is already opened by another service\"\n","stream":"stderr"}
1970-01-01T00:33:41+00:00	docker.logs	{"log":"2021-12-01 11:06:01.522469 I | embed: rejected connection from \"127.0.0.1:55430\" (error \"open /run/config/pki/etcd/server.crt: no such file or directory\", ServerName \"\")\n","stream":"stderr"}
1970-01-01T00:33:41+00:00	docker.logs	{"log":"W1201 11:06:01.522919       1 clientconn.go:1223] grpc: addrConn.createTransport failed to connect to {https://127.0.0.1:2379  <nil> 0 <nil>}. Err :connection error: desc = \"transport: authentication handshake failed: remote error: tls: internal error\". Reconnecting...\n","stream":"stderr"}
1970-01-01T00:33:41+00:00	docker.logs	{"log":"E1201 11:06:02.676549       1 dynamic_serving_content.go:165] key failed with : open /run/config/pki/front-proxy-client.crt: no such file or directory\n","stream":"stderr"}
1970-01-01T00:33:41+00:00	docker.logs	{"log":"E1201 11:06:02.676652       1 dynamic_cafile_content.go:202] key failed with : open /run/config/pki/front-proxy-ca.crt: no such file or directory\n","stream":"stderr"}
1970-01-01T00:33:41+00:00	docker.logs	{"log":"E1201 11:06:02.676595       1 dynamic_serving_content.go:165] key failed with : open /run/config/pki/apiserver.crt: no such file or directory\n","stream":"stderr"}
1970-01-01T00:33:41+00:00	docker.logs	{"log":"E1201 11:06:02.676699       1 dynamic_cafile_content.go:202] key failed with : open /run/config/pki/ca.crt: no such file or directory\n","stream":"stderr"}
1970-01-01T00:33:41+00:00	docker.logs	{"log":"E1201 11:06:02.684825       1 dynamic_cafile_content.go:202] key failed with : open /run/config/pki/front-proxy-ca.crt: no such file or directory\n","stream":"stderr"}
1970-01-01T00:33:41+00:00	docker.logs	{"log":"E1201 11:06:02.684981       1 dynamic_cafile_content.go:202] key failed with : open /run/config/pki/ca.crt: no such file or directory\n","stream":"stderr"}
1970-01-01T00:33:41+00:00	docker.logs	{"log":"Watching for file changes with StatReloader\r\n","stream":"stdout"}
1970-01-01T00:33:41+00:00	docker.logs	{"log":"Performing system checks...\r\n","stream":"stdout"}
1970-01-01T00:33:41+00:00	docker.logs	{"log":"\r\n","stream":"stdout"}
1970-01-01T00:33:41+00:00	docker.logs	{"log":"System check identified no issues (0 silenced).\r\n","stream":"stdout"}
1970-01-01T00:33:41+00:00	docker.logs	{"log":"Exception in thread django-main-thread:\r\n","stream":"stdout"}
1970-01-01T00:33:41+00:00	docker.logs	{"log":"Traceback (most recent call last):\r\n","stream":"stdout"}
1970-01-01T00:33:41+00:00	docker.logs	{"log":"  File \"/root/.local/lib/python3.9/site-packages/django/db/backends/base/base.py\", line 219, in ensure_connection\r\n","stream":"stdout"}
1970-01-01T00:33:41+00:00	docker.logs	{"log":"    self.connect()\r\n","stream":"stdout"}
1970-01-01T00:33:41+00:00	docker.logs	{"log":"  File \"/root/.local/lib/python3.9/site-packages/django/utils/asyncio.py\", line 33, in inner\r\n","stream":"stdout"}
1970-01-01T00:33:41+00:00	docker.logs	{"log":"    return func(*args, **kwargs)\r\n","stream":"stdout"}
1970-01-01T00:33:41+00:00	docker.logs	{"log":"  File \"/root/.local/lib/python3.9/site-packages/django/db/backends/base/base.py\", line 200, in connect\r\n","stream":"stdout"}
1970-01-01T00:33:41+00:00	docker.logs	{"log":"    self.connection = self.get_new_connection(conn_params)\r\n","stream":"stdout"}
1970-01-01T00:33:41+00:00	docker.logs	{"log":"  File \"/root/.local/lib/python3.9/site-packages/django/utils/asyncio.py\", line 33, in inner\r\n","stream":"stdout"}
1970-01-01T00:33:41+00:00	docker.logs	{"log":"    return func(*args, **kwargs)\r\n","stream":"stdout"}
1970-01-01T00:33:41+00:00	docker.logs	{"log":"  File \"/root/.local/lib/python3.9/site-packages/django/db/backends/mysql/base.py\", line 234, in get_new_connection\r\n","stream":"stdout"}
1970-01-01T00:33:41+00:00	docker.logs	{"log":"    connection = Database.connect(**conn_params)\r\n","stream":"stdout"}
1970-01-01T00:33:41+00:00	docker.logs	{"log":"  File \"/root/.local/lib/python3.9/site-packages/MySQLdb/__init__.py\", line 130, in Connect\r\n","stream":"stdout"}
1970-01-01T00:33:41+00:00	docker.logs	{"log":"    return Connection(*args, **kwargs)\r\n","stream":"stdout"}
1970-01-01T00:33:41+00:00	docker.logs	{"log":"  File \"/root/.local/lib/python3.9/site-packages/MySQLdb/connections.py\", line 185, in __init__\r\n","stream":"stdout"}
1970-01-01T00:33:41+00:00	docker.logs	{"log":"    super().__init__(*args, **kwargs2)\r\n","stream":"stdout"}
1970-01-01T00:33:41+00:00	docker.logs	{"log":"MySQLdb._exceptions.OperationalError: (2005, \"Unknown MySQL server host 'db-django' (-2)\")\r\n","stream":"stdout"}
1970-01-01T00:33:41+00:00	docker.logs	{"log":"\r\n","stream":"stdout"}
1970-01-01T00:33:41+00:00	docker.logs	{"log":"The above exception was the direct cause of the following exception:\r\n","stream":"stdout"}
1970-01-01T00:33:41+00:00	docker.logs	{"log":"\r\n","stream":"stdout"}
1970-01-01T00:33:41+00:00	docker.logs	{"log":"Traceback (most recent call last):\r\n","stream":"stdout"}
1970-01-01T00:33:41+00:00	docker.logs	{"log":"  File \"/usr/local/lib/python3.9/threading.py\", line 973, in _bootstrap_inner\r\n","stream":"stdout"}
1970-01-01T00:33:41+00:00	docker.logs	{"log":"    self.run()\r\n","stream":"stdout"}
1970-01-01T00:33:41+00:00	docker.logs	{"log":"  File \"/usr/local/lib/python3.9/threading.py\", line 910, in run\r\n","stream":"stdout"}
1970-01-01T00:33:41+00:00	docker.logs	{"log":"    self._target(*self._args, **self._kwargs)\r\n","stream":"stdout"}
1970-01-01T00:33:41+00:00	docker.logs	{"log":"  File \"/root/.local/lib/python3.9/site-packages/django/utils/autoreload.py\", line 64, in wrapper\r\n","stream":"stdout"}
1970-01-01T00:33:41+00:00	docker.logs	{"log":"    fn(*args, **kwargs)\r\n","stream":"stdout"}
1970-01-01T00:33:41+00:00	docker.logs	{"log":"  File \"/root/.local/lib/python3.9/site-packages/django/core/management/commands/runserver.py\", line 121, in inner_run\r\n","stream":"stdout"}
1970-01-01T00:33:41+00:00	docker.logs	{"log":"    self.check_migrations()\r\n","stream":"stdout"}
1970-01-01T00:33:41+00:00	docker.logs	{"log":"  File \"/root/.local/lib/python3.9/site-packages/django/core/management/base.py\", line 486, in check_migrations\r\n","stream":"stdout"}
1970-01-01T00:33:41+00:00	docker.logs	{"log":"    executor = MigrationExecutor(connections[DEFAULT_DB_ALIAS])\r\n","stream":"stdout"}
1970-01-01T00:33:41+00:00	docker.logs	{"log":"  File \"/root/.local/lib/python3.9/site-packages/django/db/migrations/executor.py\", line 18, in __init__\r\n","stream":"stdout"}
1970-01-01T00:33:41+00:00	docker.logs	{"log":"    self.loader = MigrationLoader(self.connection)\r\n","stream":"stdout"}
1970-01-01T00:33:41+00:00	docker.logs	{"log":"  File \"/root/.local/lib/python3.9/site-packages/django/db/migrations/loader.py\", line 53, in __init__\r\n","stream":"stdout"}
1970-01-01T00:33:41+00:00	docker.logs	{"log":"    self.build_graph()\r\n","stream":"stdout"}
1970-01-01T00:33:41+00:00	docker.logs	{"log":"  File \"/root/.local/lib/python3.9/site-packages/django/db/migrations/loader.py\", line 220, in build_graph\r\n","stream":"stdout"}
1970-01-01T00:33:41+00:00	docker.logs	{"log":"    self.applied_migrations = recorder.applied_migrations()\r\n","stream":"stdout"}
1970-01-01T00:33:41+00:00	docker.logs	{"log":"  File \"/root/.local/lib/python3.9/site-packages/django/db/migrations/recorder.py\", line 77, in applied_migrations\r\n","stream":"stdout"}
1970-01-01T00:33:41+00:00	docker.logs	{"log":"    if self.has_table():\r\n","stream":"stdout"}
1970-01-01T00:33:41+00:00	docker.logs	{"log":"  File \"/root/.local/lib/python3.9/site-packages/django/db/migrations/recorder.py\", line 55, in has_table\r\n","stream":"stdout"}
1970-01-01T00:33:41+00:00	docker.logs	{"log":"    with self.connection.cursor() as cursor:\r\n","stream":"stdout"}
1970-01-01T00:33:41+00:00	docker.logs	{"log":"  File \"/root/.local/lib/python3.9/site-packages/django/utils/asyncio.py\", line 33, in inner\r\n","stream":"stdout"}
1970-01-01T00:33:41+00:00	docker.logs	{"log":"    return func(*args, **kwargs)\r\n","stream":"stdout"}
1970-01-01T00:33:41+00:00	docker.logs	{"log":"  File \"/root/.local/lib/python3.9/site-packages/django/db/backends/base/base.py\", line 259, in cursor\r\n","stream":"stdout"}
1970-01-01T00:33:41+00:00	docker.logs	{"log":"    return self._cursor()\r\n","stream":"stdout"}
1970-01-01T00:33:41+00:00	docker.logs	{"log":"  File \"/root/.local/lib/python3.9/site-packages/django/db/backends/base/base.py\", line 235, in _cursor\r\n","stream":"stdout"}
1970-01-01T00:33:41+00:00	docker.logs	{"log":"    self.ensure_connection()\r\n","stream":"stdout"}
1970-01-01T00:33:41+00:00	docker.logs	{"log":"  File \"/root/.local/lib/python3.9/site-packages/django/utils/asyncio.py\", line 33, in inner\r\n","stream":"stdout"}
1970-01-01T00:33:41+00:00	docker.logs	{"log":"    return func(*args, **kwargs)\r\n","stream":"stdout"}
1970-01-01T00:33:41+00:00	docker.logs	{"log":"  File \"/root/.local/lib/python3.9/site-packages/django/db/backends/base/base.py\", line 219, in ensure_connection\r\n","stream":"stdout"}
1970-01-01T00:33:41+00:00	docker.logs	{"log":"    self.connect()\r\n","stream":"stdout"}
1970-01-01T00:33:41+00:00	docker.logs	{"log":"  File \"/root/.local/lib/python3.9/site-packages/django/db/utils.py\", line 90, in __exit__\r\n","stream":"stdout"}
1970-01-01T00:33:41+00:00	docker.logs	{"log":"    raise dj_exc_value.with_traceback(traceback) from exc_value\r\n","stream":"stdout"}
1970-01-01T00:33:41+00:00	docker.logs	{"log":"  File \"/root/.local/lib/python3.9/site-packages/django/db/backends/base/base.py\", line 219, in ensure_connection\r\n","stream":"stdout"}
1970-01-01T00:33:41+00:00	docker.logs	{"log":"    self.connect()\r\n","stream":"stdout"}
1970-01-01T00:33:41+00:00	docker.logs	{"log":"  File \"/root/.local/lib/python3.9/site-packages/django/utils/asyncio.py\", line 33, in inner\r\n","stream":"stdout"}
1970-01-01T00:33:41+00:00	docker.logs	{"log":"    return func(*args, **kwargs)\r\n","stream":"stdout"}
1970-01-01T00:33:41+00:00	docker.logs	{"log":"  File \"/root/.local/lib/python3.9/site-packages/django/db/backends/base/base.py\", line 200, in connect\r\n","stream":"stdout"}
1970-01-01T00:33:41+00:00	docker.logs	{"log":"    self.connection = self.get_new_connection(conn_params)\r\n","stream":"stdout"}
1970-01-01T00:33:41+00:00	docker.logs	{"log":"  File \"/root/.local/lib/python3.9/site-packages/django/utils/asyncio.py\", line 33, in inner\r\n","stream":"stdout"}
1970-01-01T00:33:41+00:00	docker.logs	{"log":"    return func(*args, **kwargs)\r\n","stream":"stdout"}
1970-01-01T00:33:41+00:00	docker.logs	{"log":"  File \"/root/.local/lib/python3.9/site-packages/django/db/backends/mysql/base.py\", line 234, in get_new_connection\r\n","stream":"stdout"}
1970-01-01T00:33:41+00:00	docker.logs	{"log":"    connection = Database.connect(**conn_params)\r\n","stream":"stdout"}
1970-01-01T00:33:41+00:00	docker.logs	{"log":"  File \"/root/.local/lib/python3.9/site-packages/MySQLdb/__init__.py\", line 130, in Connect\r\n","stream":"stdout"}
1970-01-01T00:33:41+00:00	docker.logs	{"log":"    return Connection(*args, **kwargs)\r\n","stream":"stdout"}
1970-01-01T00:33:41+00:00	docker.logs	{"log":"  File \"/root/.local/lib/python3.9/site-packages/MySQLdb/connections.py\", line 185, in __init__\r\n","stream":"stdout"}
1970-01-01T00:33:41+00:00	docker.logs	{"log":"    super().__init__(*args, **kwargs2)\r\n","stream":"stdout"}
1970-01-01T00:33:41+00:00	docker.logs	{"log":"django.db.utils.OperationalError: (2005, \"Unknown MySQL server host 'db-django' (-2)\")\r\n","stream":"stdout"}
1970-01-01T00:33:41+00:00	docker.logs	{"log":"2021-12-01 11:06:06.224702 I | embed: rejected connection from \"127.0.0.1:55472\" (error \"open /run/config/pki/etcd/server.crt: no such file or directory\", ServerName \"\")\n","stream":"stderr"}
1970-01-01T00:33:41+00:00	docker.logs	{"log":"W1201 11:06:06.226110       1 clientconn.go:1223] grpc: addrConn.createTransport failed to connect to {https://127.0.0.1:2379  <nil> 0 <nil>}. Err :connection error: desc = \"transport: authentication handshake failed: remote error: tls: internal error\". Reconnecting...\n","stream":"stderr"}
1970-01-01T00:33:41+00:00	docker.logs	{"log":"E1201 11:06:06.817108       1 dynamic_serving_content.go:165] key failed with : open /run/config/pki/ca.crt: no such file or directory\n","stream":"stderr"}
1970-01-01T00:33:41+00:00	docker.logs	{"log":"E1201 11:06:06.818385       1 dynamic_serving_content.go:165] key failed with : open /run/config/pki/ca.crt: no such file or directory\n","stream":"stderr"}
1970-01-01T00:33:41+00:00	docker.logs	{"log":"E1201 11:06:06.818508       1 dynamic_serving_content.go:165] key failed with : open /run/config/pki/ca.crt: no such file or directory\n","stream":"stderr"}
1970-01-01T00:33:41+00:00	docker.logs	{"log":"E1201 11:06:06.818567       1 dynamic_serving_content.go:165] key failed with : open /run/config/pki/ca.crt: no such file or directory\n","stream":"stderr"}
1970-01-01T00:33:41+00:00	docker.logs	{"log":"W1201 11:06:08.591088       1 watcher.go:220] watch chan error: etcdserver: mvcc: required revision has been compacted\n","stream":"stderr"}
1970-01-01T00:33:41+00:00	docker.logs	{"log":"2021-12-01 11:06:09.411408 I | etcdserver/api/etcdhttp: /health OK (status code 200)\n","stream":"stderr"}
1970-01-01T00:33:41+00:00	docker.logs	{"log":"E1201 11:06:13.126767       1 horizontal.go:227] failed to query scale subresource for Deployment/default/dj-app-deployment: deployments/scale.apps \"dj-app-deployment\" not found\n","stream":"stderr"}
1970-01-01T00:33:41+00:00	docker.logs	{"log":"I1201 11:06:13.128672       1 event.go:291] \"Event occurred\" object=\"default/dj-app-hpa\" kind=\"HorizontalPodAutoscaler\" apiVersion=\"autoscaling/v2beta2\" type=\"Warning\" reason=\"FailedGetScale\" message=\"deployments/scale.apps \\\"dj-app-deployment\\\" not found\"\n","stream":"stderr"}
1970-01-01T00:33:41+00:00	docker.logs	{"log":"E1201 11:06:13.139255       1 horizontal.go:227] failed to query scale subresource for Deployment/default/fl-app-deployment: deployments/scale.apps \"fl-app-deployment\" not found\n","stream":"stderr"}
1970-01-01T00:33:41+00:00	docker.logs	{"log":"I1201 11:06:13.139938       1 event.go:291] \"Event occurred\" object=\"default/fl-app-hpa\" kind=\"HorizontalPodAutoscaler\" apiVersion=\"autoscaling/v2beta2\" type=\"Warning\" reason=\"FailedGetScale\" message=\"deployments/scale.apps \\\"fl-app-deployment\\\" not found\"\n","stream":"stderr"}
1970-01-01T00:33:41+00:00	docker.logs	{"log":"W1201 11:06:13.753037       1 clientconn.go:1223] grpc: addrConn.createTransport failed to connect to {https://127.0.0.1:2379  <nil> 0 <nil>}. Err :connection error: desc = \"transport: authentication handshake failed: remote error: tls: internal error\". Reconnecting...\n","stream":"stderr"}
1970-01-01T00:33:41+00:00	docker.logs	{"log":"2021-12-01 11:06:13.752627 I | embed: rejected connection from \"127.0.0.1:55536\" (error \"open /run/config/pki/etcd/server.crt: no such file or directory\", ServerName \"\")\n","stream":"stderr"}
1970-01-01T00:33:41+00:00	docker.logs	{"log":"2021-12-01 11:06:19.415096 I | etcdserver/api/etcdhttp: /health OK (status code 200)\n","stream":"stderr"}
1970-01-01T00:33:41+00:00	docker.logs	{"log":"W1201 11:06:19.976936       1 watcher.go:220] watch chan error: etcdserver: mvcc: required revision has been compacted\n","stream":"stderr"}
